<sdf version='1.11'>
  <model name='AEP_Robot'>
    <plugin filename='gz-sim8-imu-system' name='gz::sim::systems::Imu'/>
    <link name='base_footprint'>
      <inertial>
        <pose>-0.0021456169080571802 0.0062815696984499471 0.07 0 0 0</pose>
        <mass>17.236799999999999</mass>
        <inertia>
          <ixx>0.68051047690503075</ixx>
          <ixy>3.8335288472801932e-05</ixy>
          <ixz>0.040272502581654518</ixz>
          <iyy>0.60604033267438095</iyy>
          <iyz>0.0020909274938807169</iyz>
          <izz>0.15954483661093849</izz>
        </inertia>
      </inertial>
      <collision name='base_footprint_fixed_joint_lump__base_link_collision'>
        <pose>0 0 0.06 0 0 0</pose>
        <geometry>
          <box>
            <size>0.45 0.32 0.08</size>
          </box>
        </geometry>
      </collision>
      <collision name='base_footprint_fixed_joint_lump__imu_link_collision_1'>
        <pose>0 0 0.14999999999999999 0 0 0</pose>
        <geometry>
          <box>
            <size>0.02 0.02 0.01</size>
          </box>
        </geometry>
      </collision>
      <collision name='base_footprint_fixed_joint_lump__lidar_link_collision_2'>
        <pose>0 0.00042039343120083499 0.32565 0 0 0</pose>
        <geometry>
          <mesh>
            <scale>1 1 1</scale>
            <uri>model://robot_description/meshes/lidar_link.STL</uri>
          </mesh>
        </geometry>
      </collision>
      <visual name='base_footprint_fixed_joint_lump__base_link_visual'>
        <pose>0 0 0 0 0 0</pose>
        <geometry>
          <mesh>
            <scale>1 1 1</scale>
            <uri>model://robot_description/meshes/base_link.STL</uri>
          </mesh>
        </geometry>
        <material>
          <diffuse>0.625 0.625 0.625 1</diffuse>
          <ambient>0.625 0.625 0.625 1</ambient>
        </material>
      </visual>
      <visual name='base_footprint_fixed_joint_lump__imu_link_visual_1'>
        <pose>0 0 0.14999999999999999 0 0 0</pose>
        <geometry>
          <box>
            <size>0.02 0.02 0.01</size>
          </box>
        </geometry>
        <material>
          <diffuse>0 1 0 0.5</diffuse>
          <ambient>0 1 0 0.5</ambient>
        </material>
      </visual>
      <visual name='base_footprint_fixed_joint_lump__lidar_link_visual_2'>
        <pose>0 0.00042039343120083499 0.32565 0 0 0</pose>
        <geometry>
          <mesh>
            <scale>1 1 1</scale>
            <uri>model://robot_description/meshes/lidar_link.STL</uri>
          </mesh>
        </geometry>
        <material>
          <diffuse>0.25 0.875 1 1</diffuse>
          <ambient>0.25 0.875 1 1</ambient>
        </material>
      </visual>
      <sensor name='lidar' type='gpu_lidar'>
        <pose>0 0.00042039343120083499 0.32565 0 0 0</pose>
        <always_on>true</always_on>
        <update_rate>10</update_rate>
        <visualize>true</visualize>
        <topic>/scan</topic>
        <ray>
          <scan>
            <horizontal>
              <samples>360</samples>
              <resolution>1</resolution>
              <min_angle>-3.14159</min_angle>
              <max_angle>3.14159</max_angle>
            </horizontal>
          </scan>
          <range>
            <min>0.12</min>
            <max>12.0</max>
            <resolution>0.01</resolution>
          </range>
          <noise>
            <type>gaussian</type>
            <mean>0.0</mean>
            <stddev>0.01</stddev>
          </noise>
        </ray>
      </sensor>
      <sensor name='imu' type='imu'>
        <pose>0 0 0.14999999999999999 0 0 0</pose>
        <always_on>true</always_on>
        <update_rate>50</update_rate>
        <topic>/imu/data</topic>
        <imu>
          <angular_velocity>
            <x>
              <noise type='gaussian'>
                <mean>0.0</mean>
                <stddev>0.0002</stddev>
              </noise>
            </x>
            <y>
              <noise type='gaussian'>
                <mean>0.0</mean>
                <stddev>0.0002</stddev>
              </noise>
            </y>
            <z>
              <noise type='gaussian'>
                <mean>0.0</mean>
                <stddev>0.0002</stddev>
              </noise>
            </z>
          </angular_velocity>
          <linear_acceleration>
            <x>
              <noise type='gaussian'>
                <mean>0.0</mean>
                <stddev>0.0004</stddev>
              </noise>
            </x>
            <y>
              <noise type='gaussian'>
                <mean>0.0</mean>
                <stddev>0.0004</stddev>
              </noise>
            </y>
            <z>
              <noise type='gaussian'>
                <mean>0.0</mean>
                <stddev>0.0004</stddev>
              </noise>
            </z>
          </linear_acceleration>
        </imu>
      </sensor>
    </link>
    <joint name='back_castor_body_joint' type='revolute'>
      <pose relative_to='base_footprint'>-0.105 0 -0.041500000000000002 0 0 0</pose>
      <parent>base_footprint</parent>
      <child>back_castor_body_link</child>
      <axis>
        <xyz>0 0 1</xyz>
        <limit>
          <lower>-inf</lower>
          <upper>inf</upper>
        </limit>
        <dynamics>
          <spring_reference>0</spring_reference>
          <spring_stiffness>0</spring_stiffness>
        </dynamics>
      </axis>
    </joint>
    <link name='back_castor_body_link'>
      <pose relative_to='back_castor_body_joint'>0 0 0 0 0 0</pose>
      <inertial>
        <pose>-0.0055142000000000004 -0.00031498000000000002 -0.0066169000000000002 0 0 0</pose>
        <mass>0.011291000000000001</mass>
        <inertia>
          <ixx>4.0602999999999999e-06</ixx>
          <ixy>1.3027999999999999e-08</ixy>
          <ixz>-8.6797000000000001e-07</ixz>
          <iyy>3.8333999999999996e-06</iyy>
          <iyz>-4.9618000000000001e-08</iyz>
          <izz>4.4634000000000003e-06</izz>
        </inertia>
      </inertial>
      <collision name='back_castor_body_link_collision'>
        <pose>0 0 0 0 0 0</pose>
        <geometry>
          <box>
            <size>0.06 0.06 0.04</size>
          </box>
        </geometry>
      </collision>
      <visual name='back_castor_body_link_visual'>
        <pose>0 0 0 0 0 0</pose>
        <geometry>
          <mesh>
            <scale>1 1 1</scale>
            <uri>model://robot_description/meshes/back_castor_body_link.STL</uri>
          </mesh>
        </geometry>
        <material>
          <diffuse>0.5 0.5 0.5 1</diffuse>
          <ambient>0.5 0.5 0.5 1</ambient>
        </material>
      </visual>
    </link>
    <joint name='back_castor_wheel_joint' type='revolute'>
      <pose relative_to='back_castor_body_link'>-0.024216000000000001 0.020653999999999999 -0.033000000000000002 0 0 0</pose>
      <parent>back_castor_body_link</parent>
      <child>back_castor_wheel_link</child>
      <axis>
        <xyz>0 1 0</xyz>
        <limit>
          <lower>-inf</lower>
          <upper>inf</upper>
        </limit>
        <dynamics>
          <spring_reference>0</spring_reference>
          <spring_stiffness>0</spring_stiffness>
        </dynamics>
      </axis>
    </joint>
    <link name='back_castor_wheel_link'>
      <pose relative_to='back_castor_wheel_joint'>0 0 0 0 0 0</pose>
      <inertial>
        <pose>0.0012650000000000001 -0.021964000000000001 -2.6983999999999999e-06 0 0 0</pose>
        <mass>0.047259000000000002</mass>
        <inertia>
          <ixx>9.5208000000000004e-06</ixx>
          <ixy>-2.6579e-07</ixy>
          <ixz>-1.9877000000000001e-09</ixz>
          <iyy>1.4164e-05</iyy>
          <iyz>-1.1341e-10</iyz>
          <izz>9.4973999999999999e-06</izz>
        </inertia>
      </inertial>
      <collision name='back_castor_wheel_link_collision'>
        <pose>0 0 0 1.5708 0 0</pose>
        <geometry>
          <cylinder>
            <length>0.02</length>
            <radius>0.03</radius>
          </cylinder>
        </geometry>
        <surface>
          <friction>
            <ode>
              <mu>1.0</mu>
              <mu2>1.0</mu2>
            </ode>
          </friction>
        </surface>
      </collision>
      <visual name='back_castor_wheel_link_visual'>
        <pose>0 0 0 0 0 0</pose>
        <geometry>
          <mesh>
            <scale>1 1 1</scale>
            <uri>model://robot_description/meshes/back_castor_wheel_link.STL</uri>
          </mesh>
        </geometry>
        <material>
          <diffuse>0.75000006 0.75000006 0.75000006 1</diffuse>
          <ambient>0.75000006 0.75000006 0.75000006 1</ambient>
        </material>
      </visual>
    </link>
    <joint name='front_castor_body_joint' type='revolute'>
      <pose relative_to='base_footprint'>0.105 0 -0.041500000000000002 0 0 0</pose>
      <parent>base_footprint</parent>
      <child>front_castor_body_link</child>
      <axis>
        <xyz>0 0 1</xyz>
        <limit>
          <lower>-inf</lower>
          <upper>inf</upper>
        </limit>
        <dynamics>
          <spring_reference>0</spring_reference>
          <spring_stiffness>0</spring_stiffness>
        </dynamics>
      </axis>
    </joint>
    <link name='front_castor_body_link'>
      <pose relative_to='front_castor_body_joint'>0 0 0 0 0 0</pose>
      <inertial>
        <pose>0.0055132999999999996 0.00033058000000000002 -0.0066169000000000002 0 0 0</pose>
        <mass>0.011291000000000001</mass>
        <inertia>
          <ixx>4.0602999999999999e-06</ixx>
          <ixy>1.3669999999999999e-08</ixy>
          <ixz>8.6782e-07</ixz>
          <iyy>3.8334999999999998e-06</iyy>
          <iyz>5.2075000000000001e-08</iyz>
          <izz>4.4634000000000003e-06</izz>
        </inertia>
      </inertial>
      <collision name='front_castor_body_link_collision'>
        <pose>0 0 0 0 0 0</pose>
        <geometry>
          <box>
            <size>0.06 0.06 0.04</size>
          </box>
        </geometry>
      </collision>
      <visual name='front_castor_body_link_visual'>
        <pose>0 0 0 0 0 0</pose>
        <geometry>
          <mesh>
            <scale>1 1 1</scale>
            <uri>model://robot_description/meshes/front_castor_body_link.STL</uri>
          </mesh>
        </geometry>
        <material>
          <diffuse>0.5 0.5 0.5 1</diffuse>
          <ambient>0.5 0.5 0.5 1</ambient>
        </material>
      </visual>
    </link>
    <joint name='front_castor_wheel_joint' type='revolute'>
      <pose relative_to='front_castor_body_link'>0.021642999999999999 0.023335999999999999 -0.033000000000000002 0 0 0</pose>
      <parent>front_castor_body_link</parent>
      <child>front_castor_wheel_link</child>
      <axis>
        <xyz>0 1 0</xyz>
        <limit>
          <lower>-inf</lower>
          <upper>inf</upper>
        </limit>
        <dynamics>
          <spring_reference>0</spring_reference>
          <spring_stiffness>0</spring_stiffness>
        </dynamics>
      </axis>
    </joint>
    <link name='front_castor_wheel_link'>
      <pose relative_to='front_castor_wheel_joint'>0 0 0 0 0 0</pose>
      <inertial>
        <pose>0.0013270000000000001 -0.02196 3.518e-06 0 0 0</pose>
        <mass>0.047259000000000002</mass>
        <inertia>
          <ixx>9.5220999999999999e-06</ixx>
          <ixy>-2.7894999999999999e-07</ixy>
          <ixz>2.5434000000000001e-09</ixz>
          <iyy>1.4161999999999999e-05</iyy>
          <iyz>1.5233999999999999e-10</iyz>
          <izz>9.4977000000000006e-06</izz>
        </inertia>
      </inertial>
      <collision name='front_castor_wheel_link_collision'>
        <pose>0 0 0 1.5708 0 0</pose>
        <geometry>
          <cylinder>
            <length>0.02</length>
            <radius>0.03</radius>
          </cylinder>
        </geometry>
        <surface>
          <friction>
            <ode>
              <mu>1.0</mu>
              <mu2>1.0</mu2>
            </ode>
          </friction>
        </surface>
      </collision>
      <visual name='front_castor_wheel_link_visual'>
        <pose>0 0 0 0 0 0</pose>
        <geometry>
          <mesh>
            <scale>1 1 1</scale>
            <uri>model://robot_description/meshes/front_castor_wheel_link.STL</uri>
          </mesh>
        </geometry>
        <material>
          <diffuse>0.75000006 0.75000006 0.75000006 1</diffuse>
          <ambient>0.75000006 0.75000006 0.75000006 1</ambient>
        </material>
      </visual>
    </link>
    <joint name='left_wheel_joint' type='revolute'>
      <pose relative_to='base_footprint'>0 0.29485 -0.025000000000000001 0 0 0</pose>
      <parent>base_footprint</parent>
      <child>left_wheel_link</child>
      <axis>
        <xyz>0 1 0</xyz>
        <limit>
          <lower>-inf</lower>
          <upper>inf</upper>
        </limit>
        <dynamics>
          <spring_reference>0</spring_reference>
          <spring_stiffness>0</spring_stiffness>
        </dynamics>
      </axis>
    </joint>
    <link name='left_wheel_link'>
      <pose relative_to='left_wheel_joint'>0 0 0 0 0 0</pose>
      <inertial>
        <pose>8.2109999999999999e-08 -0.017521999999999999 -4.1792999999999998e-07 0 0 0</pose>
        <mass>0.58299999999999996</mass>
        <inertia>
          <ixx>0.00092026</ixx>
          <ixy>2.1255000000000001e-10</ixy>
          <ixz>8.2653999999999999e-07</ixz>
          <iyy>0.0017198000000000001</iyy>
          <iyz>-1.099e-09</iyz>
          <izz>0.00091447000000000002</izz>
        </inertia>
      </inertial>
      <collision name='left_wheel_link_collision'>
        <pose>0 0 0 1.5708 0 0</pose>
        <geometry>
          <cylinder>
            <length>0.050000000000000003</length>
            <radius>0.10000000000000001</radius>
          </cylinder>
        </geometry>
        <surface>
          <friction>
            <ode>
              <mu>1.2</mu>
              <mu2>1.2</mu2>
            </ode>
          </friction>
        </surface>
      </collision>
      <visual name='left_wheel_link_visual'>
        <pose>0 0 0 0 0 0</pose>
        <geometry>
          <mesh>
            <scale>1 1 1</scale>
            <uri>model://robot_description/meshes/left_wheel_link.STL</uri>
          </mesh>
        </geometry>
        <material>
          <diffuse>0.875 0.125 1 1</diffuse>
          <ambient>0.875 0.125 1 1</ambient>
        </material>
      </visual>
    </link>
    <joint name='right_wheel_joint' type='revolute'>
      <pose relative_to='base_footprint'>0 -0.29485 -0.025000000000000001 0 0 0</pose>
      <parent>base_footprint</parent>
      <child>right_wheel_link</child>
      <axis>
        <xyz>0 1 0</xyz>
        <limit>
          <lower>-inf</lower>
          <upper>inf</upper>
        </limit>
        <dynamics>
          <spring_reference>0</spring_reference>
          <spring_stiffness>0</spring_stiffness>
        </dynamics>
      </axis>
    </joint>
    <link name='right_wheel_link'>
      <pose relative_to='right_wheel_joint'>0 0 0 0 0 0</pose>
      <inertial>
        <pose>3.8173999999999998e-07 0.017521999999999999 1.8832999999999999e-07 0 0 0</pose>
        <mass>0.58299999999999996</mass>
        <inertia>
          <ixx>0.00091578999999999999</ixx>
          <ixy>-1.3235e-09</ixy>
          <ixz>-2.5693000000000001e-06</ixz>
          <iyy>0.0017198000000000001</iyy>
          <iyz>-7.3676000000000005e-10</iyz>
          <izz>0.00091892999999999999</izz>
        </inertia>
      </inertial>
      <collision name='right_wheel_link_collision'>
        <pose>0 0 0 1.5708 0 0</pose>
        <geometry>
          <cylinder>
            <length>0.050000000000000003</length>
            <radius>0.10000000000000001</radius>
          </cylinder>
        </geometry>
        <surface>
          <friction>
            <ode>
              <mu>1.2</mu>
              <mu2>1.2</mu2>
            </ode>
          </friction>
        </surface>
      </collision>
      <visual name='right_wheel_link_visual'>
        <pose>0 0 0 0 0 0</pose>
        <geometry>
          <mesh>
            <scale>1 1 1</scale>
            <uri>model://robot_description/meshes/right_wheel_link.STL</uri>
          </mesh>
        </geometry>
        <material>
          <diffuse>0.875 0.125 1 1</diffuse>
          <ambient>0.875 0.125 1 1</ambient>
        </material>
      </visual>
    </link>
    <plugin name='gz::sim::systems::JointStatePublisher' filename='gz-sim8-joint-state-publisher-system'>
      <topic>/joint_states</topic>
      <joint_name>left_wheel_joint</joint_name>
      <joint_name>right_wheel_joint</joint_name>
      <joint_name>front_castor_body_joint</joint_name>
      <joint_name>front_castor_wheel_joint</joint_name>
      <joint_name>back_castor_body_joint</joint_name>
      <joint_name>back_castor_wheel_joint</joint_name>
    </plugin>
    <plugin name='gz::sim::systems::DiffDrive' filename='gz-sim8-diff-drive-system'>
      <left_joint>left_wheel_joint</left_joint>
      <right_joint>right_wheel_joint</right_joint>
      <wheel_separation>0.5897</wheel_separation>
      <wheel_radius>0.1</wheel_radius>
      <odom_publish_frequency>50</odom_publish_frequency>
      <topic>/cmd_vel</topic>
      <odom_topic>/odom</odom_topic>
      <frame_id>odom</frame_id>
      <child_frame_id>base_footprint</child_frame_id>
      <max_linear_acceleration>0.5</max_linear_acceleration>
      <max_angular_acceleration>1.0</max_angular_acceleration>
    </plugin>
    <frame name='imu_joint' attached_to='base_link'>
      <pose>0 0 0.14999999999999999 0 0 0</pose>
    </frame>
    <frame name='imu_link' attached_to='imu_joint'>
      <pose>0 0 0 0 0 0</pose>
    </frame>
    <frame name='lidar_joint' attached_to='base_link'>
      <pose>0 0.00042039343120083499 0.32565 0 0 0</pose>
    </frame>
    <frame name='lidar_link' attached_to='lidar_joint'>
      <pose>0 0 0 0 0 0</pose>
    </frame>
    <frame name='base_footprint_joint' attached_to='base_footprint'>
      <pose>0 0 0 0 0 0</pose>
    </frame>
    <frame name='base_link' attached_to='base_footprint_joint'>
      <pose>0 0 0 0 0 0</pose>
    </frame>
  </model>
</sdf>
